<?xml version="1.0"?>
<robot xmlns:xacro="http://www.ros.org/wiki/xacro">

  <!-- Standard wheel link macro -->
  <xacro:macro name="wheel_link" params="name mass com_x com_y com_z ixx ixy ixz iyy iyz izz mesh_filename">
    <link name="${name}_link">
      <inertial>
        <origin xyz="${com_x} ${com_y} ${com_z}" rpy="0 0 0" />
        <mass value="${mass}" />
        <inertia
          ixx="${ixx}" ixy="${ixy}" ixz="${ixz}"
          iyy="${iyy}" iyz="${iyz}" izz="${izz}" />
      </inertial>
      <visual>
        <origin xyz="0 0 0" rpy="0 0 0" />
        <geometry>
          <mesh filename="${mesh_filename}" />
        </geometry>
        <material name="wheel_material"/>
      </visual>
      <collision>
        <origin xyz="0 0 0" rpy="0 0 0" />
        <geometry>
          <mesh filename="${mesh_filename}" />
        </geometry>
      </collision>
    </link>
  </xacro:macro>

  <!-- Standard wheel joint macro -->
  <xacro:macro name="wheel_joint" params="name parent x y z axis">
    <joint name="${name}_Axis" type="continuous">
      <origin xyz="${x} ${y} ${z}" rpy="0 0 0" />
      <parent link="${parent}" />
      <child link="${name}_link" />
      <axis xyz="${axis}" />
      <limit effort="0" velocity="100" />
      <dynamics damping="0.1" friction="0.1" />
    </joint>
  </xacro:macro>

  <!-- Mecanum wheel frame link macro -->
  <xacro:macro name="mecanum_wheel_frame" params="name mass com_x com_y com_z ixx ixy ixz iyy iyz izz mesh_filename">
    <link name="${name}_link">
      <inertial>
        <origin xyz="${com_x} ${com_y} ${com_z}" rpy="0 0 0" />
        <mass value="${mass}" />
        <inertia
          ixx="${ixx}" ixy="${ixy}" ixz="${ixz}"
          iyy="${iyy}" iyz="${iyz}" izz="${izz}" />
      </inertial>
      <visual>
        <origin xyz="0 0 0" rpy="0 0 0" />
        <geometry>
          <mesh filename="${mesh_filename}" />
        </geometry>
        <material name="base_material"/>
      </visual>
      <collision>
        <origin xyz="0 0 0" rpy="0 0 0" />
        <geometry>
          <mesh filename="${mesh_filename}" />
        </geometry>
      </collision>
    </link>
  </xacro:macro>

  <!-- Mecanum wheel frame joint macro -->
  <xacro:macro name="mecanum_frame_joint" params="name parent x y z">
    <joint name="${name}_Axis" type="continuous">
      <origin xyz="${x} ${y} ${z}" rpy="${pi/2} 0 ${mdw_yaw}" />
      <parent link="${parent}" />
      <child link="${name}_link" />
      <axis xyz="0 1 0" />
      <limit effort="0" velocity="100" />
      <dynamics damping="0.1" friction="0.1" />
    </joint>
  </xacro:macro>

  <!-- Mecanum wheel link macro -->
  <xacro:macro name="mecanum_wheel" params="name mass ixx ixy ixz iyy iyz izz mesh_filename">
    <link name="${name}_link">
      <inertial>
        <origin xyz="0 0 0" rpy="0 0 0" />
        <mass value="${mass}" />
        <inertia
          ixx="${ixx}" ixy="${ixy}" ixz="${ixz}"
          iyy="${iyy}" iyz="${iyz}" izz="${izz}" />
      </inertial>
      <visual>
        <origin xyz="0 0 0" rpy="0 0 0" />
        <geometry>
          <mesh filename="${mesh_filename}" />
        </geometry>
        <material name="base_material"/>
      </visual>
      <collision>
        <origin xyz="0 0 0" rpy="0 0 0" />
        <geometry>
          <mesh filename="${mesh_filename}" />
        </geometry>
      </collision>
    </link>
  </xacro:macro>

  <!-- Mecanum wheel joint macro -->
  <xacro:macro name="mecanum_wheel_joint" params="name parent x y z axis_x axis_y axis_z">
    <joint name="${name}_Axis" type="continuous">
      <origin xyz="${x} ${y} ${z}" rpy="0 0 0" />
      <parent link="${parent}" />
      <child link="${name}_link" />
      <axis xyz="${axis_x} ${axis_y} ${axis_z}" />
      <limit effort="0" velocity="100" />
      <dynamics damping="0.1" friction="0.1" />
    </joint>
  </xacro:macro>

  <!-- Sensor link macro (like IMU, Lidar) -->
  <xacro:macro name="sensor_link" params="name mass com_x com_y com_z ixx ixy ixz iyy iyz izz color mesh_filename">
    <link name="${name}_link">
      <inertial>
        <origin xyz="${com_x} ${com_y} ${com_z}" rpy="0 0 0" />
        <mass value="${mass}" />
        <inertia
          ixx="${ixx}" ixy="${ixy}" ixz="${ixz}"
          iyy="${iyy}" iyz="${iyz}" izz="${izz}" />
      </inertial>
      <visual>
        <origin xyz="0 0 0" rpy="0 0 0" />
        <geometry>
          <mesh filename="${mesh_filename}" />
        </geometry>
        <material name="">
          <color rgba="${color} 1" />
        </material>
      </visual>
      <collision>
        <origin xyz="0 0 0" rpy="0 0 0" />
        <geometry>
          <mesh filename="${mesh_filename}" />
        </geometry>
      </collision>
    </link>
  </xacro:macro>

  <!-- Fixed joint macro -->
  <xacro:macro name="fixed_joint" params="name parent x y z roll pitch yaw">
    <joint name="${name}_link" type="fixed">
      <origin xyz="${x} ${y} ${z}" rpy="${roll} ${pitch} ${yaw}" />
      <parent link="${parent}" />
      <child link="${name}_link" />
      <axis xyz="0 0 0" />
    </joint>
  </xacro:macro>

  <!-- Continuous joint macro -->
  <xacro:macro name="continuous_joint" params="name parent x y z roll pitch yaw axis">
    <joint name="${name}_link" type="continuous">
      <origin xyz="${x} ${y} ${z}" rpy="${roll} ${pitch} ${yaw}" />
      <parent link="${parent}" />
      <child link="${name}_link" />
      <axis xyz="${axis}" />
    </joint>
  </xacro:macro>

</robot> 